Workbook

Sheet Master Data & Assumptions
B1: Logistics and Network Design
B2: Portfolio Output 6 · five metro clusters across seven states/UTs · 90-day operating history from 2025-09-01
B4: 5 | D4: 7 | F4: 2500 | H4: 125 | J4: 104195 | L4: 55
B5: Metro clusters | D5: States / UTs | F5: Delivery addresses | H5: Vehicles | J5: Orders (90 days) | L5: Candidate MFC sites
B7: City cluster profile
B8: City ID | C8: City cluster | D8: States / UTs | E8: Volume weight | F8: Congestion index | G8: Wage index | H8: Orders / day | I8: Peak-day orders | J8: Peak date | K8: E-com share | L8: Avg kg / order
B9: MUM | C9: Mumbai MMR | D9: Maharashtra | E9: 1 | F9: 1 | G9: 1 | H9: 278.9 | I9: 554 | J9: 45943 | K9: 0.6583 | L9: 50.8
B10: DEL | C10: Delhi NCR | D10: Delhi, Haryana, Uttar Pradesh | E10: 1.05 | F10: 0.95 | G10: 1 | H10: 292.3 | I10: 524 | J10: 45947 | K10: 0.6634 | L10: 49.6
B11: BLR | C11: Bengaluru | D11: Karnataka | E11: 0.85 | F11: 1.12 | G11: 1.02 | H11: 233.7 | I11: 430 | J11: 45943 | K11: 0.6594 | L11: 49.6
B12: CHE | C12: Chennai | D12: Tamil Nadu | E12: 0.7 | F12: 0.92 | G12: 0.92 | H12: 191.6 | I12: 368 | J12: 45943 | K12: 0.6627 | L12: 50.3
B13: KOL | C13: Kolkata | D13: West Bengal | E13: 0.6 | F13: 1.05 | G13: 0.85 | H13: 161.3 | I13: 349 | J13: 45943 | K13: 0.6603 | L13: 50.3
K15: Scenario levers (editable)
K16: Blue = input; Facility Economics recalculates from these cells.
K17: WACC | M17: 0.12
K18: Demand growth / year | M18: 0.18
K19: Compliance target | M19: 0.95
K20: P95 cycle-time target (min) | M20: 120
B31: Master data register
B32: Every parameter used by the models, with unit, rationale and dependent modules (config/logistics.yaml).
B33: Parameter | C33: Value | D33: Unit | E33: Rationale | F33: Dependent modules
B34: project.seed | C34: 42 | D34: - | E34: Fixed seed so every run reproduces identical data and results | F34: all
B35: calendar.start_date | C35: 2025-09-01 | D35: date | E35: 90-day window covering monsoon tail, festive sales and Diwali | F35: data, ml, simulation
B36: calendar.days | C36: 90 | D36: days | E36: Planning history length specified for the scenario | F36: data, ml
B37: calendar.diwali_date | C37: 2025-10-20 | D37: date | E37: Diwali 2025 (Lakshmi Puja); national peak build-up precedes it | F37: data, fleet, simulation
B38: cities.MUM.volume_weight | C38: 1.0 | D38: index | E38: Mumbai MMR (Maharashtra) order volume relative to base | F38: data
B39: cities.DEL.volume_weight | C39: 1.05 | D39: index | E39: Delhi NCR (Delhi, Haryana, UP) order volume relative to base | F39: data
B40: cities.BLR.volume_weight | C40: 0.85 | D40: index | E40: Bengaluru (Karnataka) order volume relative to base | F40: data
B41: cities.CHE.volume_weight | C41: 0.7 | D41: index | E41: Chennai (Tamil Nadu) order volume relative to base | F41: data
B42: cities.KOL.volume_weight | C42: 0.6 | D42: index | E42: Kolkata (West Bengal) order volume relative to base | F42: data
B43: cities.BLR.congestion | C43: 1.12 | D43: index | E43: Observed travel-time index in Bengaluru trip logs (highest congestion) | F43: data, ml
B44: cities.CHE.rain_probability_by_month | C44: {9: 0.2, 10: 0.45, 11: 0.5} | D44: probability | E44: North-east monsoon raises Oct-Nov rain days in Chennai | F44: data, ml
... B93: network.sla_minutes | C93: 120 | D93: min | E93: Two-hour delivery promise | F93: network
B94: Colour legend: blue font = editable input; black = formula or model output; green = link to another sheet. All figures are produced by the Python modules from the operational dataset.

Sheet Depot & Vehicle Master
B1: Depot & Vehicle Master
B2: 15 depots (DC, MFC, hub per city) · 125 vehicles · vehicle economics
B4: Depot master
B5: Depot ID | C5: City | D5: State | E5: Role | F5: Depot | G5: Zone | H5: Lat | I5: Lon | J5: Vehicles | K5: Opens | L5: Closes
B6: DEP-MUM-DC | C6: Mumbai MMR | D6: Maharashtra | E6: DC | F6: Bhiwandi DC | G6: Thane | H6: 19.2813 | I6: 73.0483 | J6: 10 | K6: 07:00 | L6: 21:30
B7: DEP-MUM-MFC | C7: Mumbai MMR | D7: Maharashtra | E7: MFC | F7: Andheri MFC | G7: Andheri | H7: 19.1176 | I7: 72.8697 | J7: 7 | K7: 07:00 | L7: 21:30
B8: DEP-MUM-HUB | C8: Mumbai MMR | D8: Maharashtra | E8: HUB | F8: Navi Mumbai Hub | G8: Navi Mumbai | H8: 19.0745 | I8: 73.017 | J8: 8 | K8: 07:00 | L8: 21:30
B9: DEP-DEL-DC | C9: Delhi NCR | D9: Delhi / Haryana / Uttar Pradesh | E9: DC | F9: Gurugram Bilaspur DC | G9: Gurugram | H9: 28.312 | I9: 76.867 | J9: 10 | K9: 07:00 | L9: 21:30
B10: DEP-DEL-MFC | C10: Delhi NCR | D10: Delhi / Haryana / Uttar Pradesh | E10: MFC | F10: Okhla MFC | G10: South Delhi | H10: 28.535 | I10: 77.278 | J10: 7 | K10: 07:00 | L10: 21:30
B11: DEP-DEL-HUB | C11: Delhi NCR | D11: Delhi / Haryana / Uttar Pradesh | E11: HUB | F11: Noida Hub | G11: Noida | H11: 28.627 | I11: 77.377 | J11: 8 | K11: 07:00 | L11: 21:30
B12: DEP-BLR-DC | C12: Bengaluru | D12: Karnataka | E12: DC | F12: Hoskote DC | G12: East Bengaluru | H12: 13.07 | I12: 77.798 | J12: 10 | K12: 07:00 | L12: 21:30
B13: DEP-BLR-MFC | C13: Bengaluru | D13: Karnataka | E13: MFC | F13: Koramangala MFC | G13: South Bengaluru | H13: 12.935 | I13: 77.624 | J13: 7 | K13: 07:00 | L13: 21:30
B14: DEP-BLR-HUB | C14: Bengaluru | D14: Karnataka | E14: HUB | F14: Peenya Hub | G14: West Bengaluru | H14: 13.03 | I14: 77.52 | J14: 8 | K14: 07:00 | L14: 21:30
B15: DEP-CHE-DC | C15: Chennai | D15: Tamil Nadu | E15: DC | F15: Sriperumbudur DC | G15: West Chennai | H15: 12.968 | I15: 79.946 | J15: 10 | K15: 07:00 | L15: 21:30
B16: DEP-CHE-MFC | C16: Chennai | D16: Tamil Nadu | E16: MFC | F16: Guindy MFC | G16: South Chennai | H16: 13.007 | I16: 80.213 | J16: 7 | K16: 07:00 | L16: 21:30
B17: DEP-CHE-HUB | C17: Chennai | D17: Tamil Nadu | E17: HUB | F17: Ambattur Hub | G17: North Chennai | H17: 13.114 | I17: 80.155 | J17: 8 | K17: 07:00 | L17: 21:30
... B20: DEP-KOL-HUB | C20: Kolkata | D20: West Bengal | E20: HUB | F20: Howrah Hub | G20: Howrah | H20: 22.595 | I20: 88.263 | J20: 8 | K20: 07:00 | L20: 21:30
B23: Vehicle types
B24: Driver wages are scaled by each city's wage index in the vehicle master.
B25: Type | C25: Label | D25: Capacity kg | E25: Speed km/h | F25: ₹ / km | G25: Fixed ₹ / day | H25: Driver ₹ / h (MUM) | I25: Duty min | J25: Max parcel kg | K25: Acquisition ₹ | L25: Lease ₹ / month | M25: Restricted zones
B26: VAN_2T | C26: 2-ton van | D26: 2000 | E26: 26 | F26: 18 | G26: 2800 | H26: 230 | I26: 600 | J26: 2000 | K26: 2400000 | L26: 62000 | M26: South Mumbai;Central Delhi;Central Bengaluru;Central Chennai;Central Kolkata
B27: TEMPO_1T | C27: 1-ton tempo | D27: 1000 | E27: 28 | F27: 13 | G27: 1900 | H27: 210 | I27: 600 | J27: 1000 | K27: 1050000 | L27: 31000
B28: TWO_WHEELER | C28: 2-wheeler | D28: 40 | E28: 30 | F28: 3.5 | G28: 450 | H28: 160 | I28: 480 | J28: 15 | K28: 115000 | L28: 4200
B31: Fleet by city and type (current)
B33: City | C33: TEMPO_1T | D33: TWO_WHEELER | E33: VAN_2T
B34: Mumbai MMR | C34: 10 | D34: 5 | E34: 10
B35: Delhi NCR | C35: 10 | D35: 5 | E35: 10
B36: Bengaluru | C36: 10 | D36: 5 | E36: 10
B37: Chennai | C37: 10 | D37: 5 | E37: 10
B38: Kolkata | C38: 10 | D38: 5 | E38: 10

Sheet Order & Demand Profile
B1: Order & Demand Profile
B2: Daily volume by city with national and regional events, segment mix and weekly heat
B4: 104195 | E4: 1157.7222 | H4: 2206 | K4: 1.7286606
B5: Orders, 90 days | E5: Average orders / day | H5: Peak day (2025-10-13) | K5: Diwali-peak uplift vs normal days
B7: Daily orders by city
B8: Date | C8: Mumbai MMR | D8: Delhi NCR | E8: Bengaluru | F8: Chennai | G8: Kolkata | H8: All cities
B9: 45901 | C9: 269 | D9: 275 | E9: 244 | F9: 226 | G9: 164 | H9: 1178
B10: 45902 | C10: 285 | D10: 293 | E10: 230 | F10: 190 | G10: 164 | H10: 1162
B11: 45903 | C11: 270 | D11: 282 | E11: 194 | F11: 177 | G11: 139 | H11: 1062
B12: 45904 | C12: 278 | D12: 263 | E12: 226 | F12: 207 | G12: 150 | H12: 1124
B13: 45905 | C13: 250 | D13: 282 | E13: 218 | F13: 173 | G13: 152 | H13: 1075
B14: 45906 | C14: 157 | D14: 242 | E14: 217 | F14: 154 | G14: 130 | H14: 900
B15: 45907 | C15: 163 | D15: 178 | E15: 148 | F15: 126 | G15: 94 | H15: 709
B16: 45908 | C16: 304 | D16: 296 | E16: 225 | F16: 180 | G16: 170 | H16: 1175
B17: 45909 | C17: 266 | D17: 282 | E17: 238 | F17: 177 | G17: 169 | H17: 1132
B18: 45910 | C18: 283 | D18: 266 | E18: 214 | F18: 201 | G18: 145 | H18: 1109
B19: 45911 | C19: 282 | D19: 256 | E19: 208 | F19: 170 | G19: 151 | H19: 1067
B20: 45912 | C20: 284 | D20: 291 | E20: 220 | F20: 180 | G20: 145 | H20: 1120
... B27: 45919 | C27: 276 | D27: 288 | E27: 256 | F27: 187 | G27: 166 | H27: 1173
B28: 45920 | C28: 228 | D28: 233 | E28: 172 | F28: 156 | G28: 144 | H28: 933 | K28: Trend by city
B29: 45921 | C29: 161 | D29: 179 | E29: 103 | F29: 108 | G29: 102 | H29: 653 | K29: City | L29: 90-day trend | M29: Min | N29: Average | O29: Max | P29: Peak date
B30: 45922 | C30: 314 | D30: 306 | E30: 241 | F30: 204 | G30: 170 | H30: 1235 | K30: Mumbai MMR | M30: =MIN(C9:C98) | N30: =AVERAGE(C9:C98) | O30: =MAX(C9:C98) | P30: =INDEX($B$9:$B$98,MATCH(MAX(C9:C98),C9:C98,0))
B31: 45923 | C31: 379 | D31: 398 | E31: 350 | F31: 267 | G31: 226 | H31: 1620 | K31: Delhi NCR | M31: =MIN(D9:D98) | N31: =AVERAGE(D9:D98) | O31: =MAX(D9:D98) | P31: =INDEX($B$9:$B$98,MATCH(MAX(D9:D98),D9:D98,0))
B32: 45924 | C32: 372 | D32: 394 | E32: 311 | F32: 250 | G32: 240 | H32: 1567 | K32: Bengaluru | M32: =MIN(E9:E98) | N32: =AVERAGE(E9:E98) | O32: =MAX(E9:E98) | P32: =INDEX($B$9:$B$98,MATCH(MAX(E9:E98),E9:E98,0))
B33: 45925 | C33: 379 | D33: 386 | E33: 318 | F33: 262 | G33: 225 | H33: 1570 | K33: Chennai | M33: =MIN(F9:F98) | N33: =AVERAGE(F9:F98) | O33: =MAX(F9:F98) | P33: =INDEX($B$9:$B$98,MATCH(MAX(F9:F98),F9:F98,0))
B34: 45926 | C34: 396 | D34: 434 | E34: 299 | F34: 236 | G34: 218 | H34: 1583 | K34: Kolkata | M34: =MIN(G9:G98) | N34: =AVERAGE(G9:G98) | O34: =MAX(G9:G98) | P34: =INDEX($B$9:$B$98,MATCH(MAX(G9:G98),G9:G98,0))
B35: 45927 | C35: 346 | D35: 365 | E35: 278 | F35: 249 | G35: 175 | H35: 1413 | K35: All cities | M35: =MIN(H9:H98) | N35: =AVERAGE(H9:H98) | O35: =MAX(H9:H98) | P35: =INDEX($B$9:$B$98,MATCH(MAX(H9:H98),H9:H98,0))
B36: 45928 | C36: 234 | D36: 261 | E36: 182 | F36: 157 | G36: 115 | H36: 949
B37: 45929 | C37: 390 | D37: 454 | E37: 359 | F37: 257 | G37: 144 | H37: 1604
B38: 45930 | C38: 415 | D38: 386 | E38: 304 | F38: 283 | G38: 141 | H38: 1529 | K38: Segment mix by city (share of orders)
B39: 45931 | C39: 360 | D39: 417 | E39: 271 | F39: 198 | G39: 150 | H39: 1396 | K39: City | L39: AUTOMOTIVE | M39: ECOM_B2C | N39: FMCG_RETAIL | O39: MODERN_RETAIL
B40: 45932 | C40: 239 | D40: 279 | E40: 209 | F40: 172 | G40: 103 | H40: 1002 | K40: Mumbai MMR | L40: 0.098282937 | M40: 0.65826063 | N40: 0.1511892 | O40: 0.09226724
B41: 45933 | C41: 396 | D41: 393 | E41: 352 | F41: 273 | G41: 201 | H41: 1615 | K41: Delhi NCR | L41: 0.098498384 | M41: 0.66341 | N41: 0.15114997 | O41: 0.086941646
B42: 45934 | C42: 322 | D42: 340 | E42: 305 | F42: 229 | G42: 186 | H42: 1382 | K42: Bengaluru | L42: 0.099795559 | M42: 0.65939238 | N42: 0.15204678 | O42: 0.088765274
B43: 45935 | C43: 215 | D43: 236 | E43: 207 | F43: 185 | G43: 139 | H43: 982 | K43: Chennai | L43: 0.099303944 | M43: 0.66270302 | N43: 0.14663573 | O43: 0.091357309
B44: 45936 | C44: 289 | D44: 329 | E44: 294 | F44: 224 | G44: 171 | H44: 1307 | K44: Kolkata | L44: 0.099683108 | M44: 0.66030587 | N44: 0.15238358 | O44: 0.087627446
B45: 45937 | C45: 292 | D45: 316 | E45: 256 | F45: 188 | G45: 181 | H45: 1233
B46: 45938 | C46: 284 | D46: 295 | E46: 238 | F46: 217 | G46: 181 | H46: 1215
B47: 45939 | C47: 239 | D47: 300 | E47: 229 | F47: 175 | G47: 172 | H47: 1115
B48: 45940 | C48: 461 | D48: 496 | E48: 397 | F48: 294 | G48: 257 | H48: 1905
...

Sheet Routing Analysis
B1: Routing Analysis
B2: CVRPTW (OR-Tools, guided local search) vs window-aware nearest-neighbour baseline · representative day 2025-09-10 · 1,109 orders
B4: =F14 | E4: =I14 | H4: =K14 | K4: =M14 | N4: =P14-Q14
B5: Last-mile cost reduction (incl. outsourcing) | E5: Fleet operating cost reduction | H5: Optimized in-window delivery | K5: Vehicles used (optimized) · vs baseline in table | N5: Road km saved
B7: Baseline vs optimized by city (formulas compute deltas and national totals)
B8: City | C8: Orders | D8: Baseline last-mile ₹ | E8: Optimized last-mile ₹ | F8: Last-mile reduction | G8: Baseline fleet ₹ | H8: Optimized fleet ₹ | I8: Fleet cost reduction | J8: Baseline compliance | K8: Optimized compliance | L8: Baseline vehicles | M8: Optimized vehicles | N8: Baseline unassigned | O8: Optimized unassigned | P8: Baseline road km | Q8: Optimized road km
B9: Mumbai MMR | C9: 283 | D9: 102638 | E9: 81833 | F9: =IFERROR(1-E9/D9,0) | G9: 102418 | H9: 81833 | I9: =IFERROR(1-H9/G9,0) | J9: 0.9929 | K9: 0.9929 | L9: 21 | M9: 18 | N9: 1 | O9: 0 | P9: 1931.4 | Q9: 1410.4
B10: Delhi NCR | C10: 266 | D10: 126986 | E10: 96405 | F10: =IFERROR(1-E10/D10,0) | G10: 118706 | H10: 85705 | I10: =IFERROR(1-H10/G10,0) | J10: 0.9286 | K10: 0.9662 | L10: 23 | M10: 18 | N10: 16 | O10: 9 | P10: 2581.5 | Q10: 1808.6
B11: Bengaluru | C11: 214 | D11: 91041 | E11: 67076 | F11: =IFERROR(1-E11/D11,0) | G11: 91041 | H11: 67076 | I11: =IFERROR(1-H11/G11,0) | J11: 0.9953 | K11: 0.9813 | L11: 19 | M11: 17 | N11: 0 | O11: 0 | P11: 1512 | Q11: 1131.6
B12: Chennai | C12: 201 | D12: 92494 | E12: 60543 | F12: =IFERROR(1-E12/D12,0) | G12: 92494 | H12: 60543 | I12: =IFERROR(1-H12/G12,0) | J12: 1 | K12: 0.995 | L12: 19 | M12: 15 | N12: 0 | O12: 0 | P12: 1828.2 | Q12: 1306.2
B13: Kolkata | C13: 145 | D13: 70667 | E13: 38676 | F13: =IFERROR(1-E13/D13,0) | G13: 70667 | H13: 38676 | I13: =IFERROR(1-H13/G13,0) | J13: 1 | K13: 0.9862 | L13: 17 | M13: 11 | N13: 0 | O13: 0 | P13: 1058.7 | Q13: 708.8
B14: All cities | C14: =SUM(C9:C13) | D14: =SUM(D9:D13) | E14: =SUM(E9:E13) | F14: =IFERROR(1-E14/D14,0) | G14: =SUM(G9:G13) | H14: =SUM(H9:H13) | I14: =IFERROR(1-H14/G14,0) | J14: =SUMPRODUCT(J9:J13,$C$9:$C$13)/SUM($C$9:$C$13) | K14: =SUMPRODUCT(K9:K13,$C$9:$C$13)/SUM($C$9:$C$13) | L14: =SUM(L9:L13) | M14: =SUM(M9:M13) | N14: =SUM(N9:N13) | O14: =SUM(O9:O13) | P14: =SUM(P9:P13) | Q14: =SUM(Q9:Q13)
B50: Baseline: window-aware nearest-neighbour dispatch (each vehicle repeatedly takes the closest order it can reach before its window closes; late second pass). Both plans are replayed by the same evaluator with departure-time traffic bands and ML zone calibration. Unserved orders are costed at spot-outsourcing rates, so 'last-mile cost' compares like-for-like service. Road km = straight-line km x 1.35 planning circuity (estimate, not routed street distance).

Sheet Route Stops & Compliance
B1: Route Stops & Compliance
B2: Zone-level service, vehicle utilisation and stop-level audit trail (optimized plan)
B4: On-time performance by zone
B5: City | C5: Zone | D5: Stops | E5: Baseline on-time | F5: Optimized on-time | G5: Avg late min | H5: Avg wait min
B6: Bengaluru | C6: Central Bengaluru | D6: 32 | E6: 1 | F6: 1 | G6: 0 | H6: 4.45625
B7: Bengaluru | C7: East Bengaluru | D7: 53 | E7: 0.98113208 | F7: 0.9245283 | G7: 1.390566 | H7: 4.0433962
B8: Bengaluru | C8: North Bengaluru | D8: 33 | E8: 1 | F8: 1 | G8: 0 | H8: 8.5666667
B9: Bengaluru | C9: South Bengaluru | D9: 61 | E9: 1 | F9: 1 | G9: 0 | H9: 8.8409836
B10: Bengaluru | C10: West Bengaluru | D10: 35 | E10: 1 | F10: 1 | G10: 0 | H10: 11.131429
B11: Chennai | C11: Central Chennai | D11: 47 | E11: 1 | F11: 1 | G11: 0 | H11: 3.8659574
B12: Chennai | C12: North Chennai | D12: 29 | E12: 1 | F12: 1 | G12: 0 | H12: 0.10689655
B13: Chennai | C13: OMR Corridor | D13: 45 | E13: 1 | F13: 0.97777778 | G13: 0.02 | H13: 6.1977778
B14: Chennai | C14: South Chennai | D14: 35 | E14: 1 | F14: 1 | G14: 0 | H14: 5.0657143
B15: Chennai | C15: West Chennai | D15: 45 | E15: 1 | F15: 1 | G15: 0 | H15: 7.2022222
B16: Delhi NCR | C16: Central Delhi | D16: 50 | E16: 1 | F16: 1 | G16: 0 | H16: 2.772
B17: Delhi NCR | C17: Gurugram | D17: 59 | E17: 1 | F17: 1 | G17: 0 | H17: 9.3745763
... B30: Mumbai MMR | C30: Thane | D30: 61 | E30: 1 | F30: 1 | G30: 0 | H30: 7.2655738
B33: Vehicle routes (optimized)
B34: Duty overrun = route exceeds driver duty limit when replayed under actual departure-time traffic; reported as overtime, not hidden.
B35: City | C35: Depot | D35: Vehicle | E35: Type | F35: Stops | G35: Load util % | H35: Duty util % | I35: Straight km | J35: Road km (est.) | K35: Duration min | L35: Wait min | M35: Late stops | N35: Duty overrun | O35: Route cost ₹
B36: Mumbai MMR | C36: DEP-MUM-DC | D36: VEH-MUM-001 | E36: VAN_2T | F36: 16 | G36: 94.9 | H36: 84.3 | I36: 67.58 | J36: 91.23 | K36: 505.9 | L36: 71.9 | M36: 0 | N36: No | O36: 6381.33
B37: Mumbai MMR | C37: DEP-MUM-DC | D37: VEH-MUM-002 | E37: VAN_2T | F37: 14 | G37: 91 | H37: 79.2 | I37: 68.22 | J37: 92.09 | K37: 474.9 | L37: 20.8 | M37: 0 | N37: No | O37: 6278.29
B38: Mumbai MMR | C38: DEP-MUM-DC | D38: VEH-MUM-003 | E38: VAN_2T | F38: 16 | G38: 92.4 | H38: 83.6 | I38: 69.36 | J38: 93.63 | K38: 501.7 | L38: 0 | M38: 2 | N38: No | O38: 6408.71
B39: Mumbai MMR | C39: DEP-MUM-DC | D39: VEH-MUM-007 | E39: TEMPO_1T | F39: 13 | G39: 92.1 | H39: 72.8 | I39: 72.81 | J39: 98.3 | K39: 436.6 | L39: 0 | M39: 0 | N39: No | O39: 4705.95
B40: Mumbai MMR | C40: DEP-MUM-DC | D40: VEH-MUM-008 | E40: TEMPO_1T | F40: 13 | G40: 84.7 | H40: 99.9 | I40: 91.97 | J40: 124.16 | K40: 599.6 | L40: 128.8 | M40: 0 | N40: No | O40: 5612.74
B41: Mumbai MMR | C41: DEP-MUM-DC | D41: VEH-MUM-009 | E41: TEMPO_1T | F41: 8 | G41: 97.6 | H41: 74 | I41: 91.34 | J41: 123.31 | K41: 444 | L41: 62.2 | M41: 0 | N41: No | O41: 5057.05
B42: Mumbai MMR | C42: DEP-MUM-DC | D42: VEH-MUM-010 | E42: TEMPO_1T | F42: 22 | G42: 97.2 | H42: 92.7 | I42: 93.2 | J42: 125.82 | K42: 556.1 | L42: 51.3 | M42: 0 | N42: No | O42: 5482.04
B43: Mumbai MMR | C43: DEP-MUM-MFC | D43: VEH-MUM-012 | E43: TEMPO_1T | F43: 35 | G43: 12.6 | H43: 90.8 | I43: 67.5 | J43: 91.12 | K43: 544.6 | L43: 156.4 | M43: 0 | N43: No | O43: 4990.53
B44: Mumbai MMR | C44: DEP-MUM-MFC | D44: VEH-MUM-013 | E44: TEMPO_1T | F44: 29 | G44: 11 | H44: 78.2 | I44: 61.11 | J44: 82.5 | K44: 469.5 | L44: 115 | M44: 0 | N44: No | O44: 4615.63
B45: Mumbai MMR | C45: DEP-MUM-MFC | D45: VEH-MUM-014 | E45: TEMPO_1T | F45: 32 | G45: 10.9 | H45: 102.8 | I45: 34.9 | J45: 47.12 | K45: 617 | L45: 320.1 | M45: 0 | N45: Yes | O45: 4672.09
B46: Mumbai MMR | C46: DEP-MUM-MFC | D46: VEH-MUM-015 | E46: TWO_WHEELER | F46: 6 | G46: 58.7 | H46: 66.1 | I46: 27.66 | J46: 37.33 | K46: 317.3 | L46: 172.7 | M46: 0 | N46: No | O46: 1426.68
B47: Mumbai MMR | C47: DEP-MUM-MFC | D47: VEH-MUM-016 | E47: TWO_WHEELER | F47: 7 | G47: 70.1 | H47: 47 | I47: 34.24 | J47: 46.22 | K47: 225.6 | L47: 57.5 | M47: 0 | N47: No | O47: 1213.25
... B114: Kolkata | C114: DEP-KOL-HUB | D114: VEH-KOL-024 | E114: TWO_WHEELER | F114: 15 | G114: 72.3 | H114: 105.6 | I114: 59.93 | J114: 80.9 | K114: 506.9 | L114: 201.7 | M114: 0 | N114: Yes | O114: 1882.14
B117: Unassigned orders in the optimized plan (9)
B118: Explicitly reported and costed at the spot-outsourcing rate.
B119: order_id | C119: city_id | D119: depot_id | E119: segment | F119: zone | G119: weight_kg | H119: tw_start_min | I119: tw_end_min | J119: outsourcing_cost | K119: reason
B120: ORD-DEL-002423 | C120: DEL | D120: DEP-DEL-MFC | E120: ECOM_B2C | F120: Gurugram | G120: 4.59 | H120: 1080 | I120: 1200 | J120: 220 | K120: capacity/time-window/duration limits
B121: ORD-DEL-002440 | C121: DEL | D121: DEP-DEL-MFC | E121: ECOM_B2C | F121: West Delhi | G121: 6.86 | H121: 540 | I121: 720 | J121: 220 | K121: capacity/time-window/duration limits
B122: ORD-DEL-002526 | C122: DEL | D122: DEP-DEL-MFC | E122: ECOM_B2C | F122: West Delhi | G122: 12.23 | H122: 540 | I122: 720 | J122: 220 | K122: capacity/time-window/duration limits
B123: ORD-DEL-002531 | C123: DEL | D123: DEP-DEL-MFC | E123: ECOM_B2C | F123: West Delhi | G123: 2.04 | H123: 540 | I123: 720 | J123: 220 | K123: capacity/time-window/duration limits
...

Sheet Fleet Sizing
B1: Fleet Sizing
B2: Minimum fleet and vehicle mix per demand level (fleet-size-and-mix CVRPTW) · own vs lease TCO
B4: 87 | E4: 1 | H4: 277 | K4: 1
B5: Recommended fleet at 1.0x (all cities) · current 125 | E5: Highest level the current fleet serves at target | H5: Fleet needed at 3x (highest level modelled) | K5: Infeasible city-levels
B7: Recommended fleet by demand level
B8: Demand level | C8: Mumbai MMR | D8: Delhi NCR | E8: Bengaluru | F8: Chennai | G8: Kolkata
B9: 0.5 | C9: 14 | D9: 16 | E9: 12 | F9: 11 | G9: 8
B10: 0.75 | C10: 18 | D10: 18 | E10: 15 | F10: 13 | G10: 11
B11: 1 | C11: 20 | D11: 21 | E11: 18 | F11: 16 | G11: 12
B12: 1.5 | C12: 29 | D12: 32 | E12: 26 | F12: 23 | G12: 16
B13: 2 | C13: 40 | D13: 41 | E13: 35 | F13: 31 | G13: 23
B14: 3 | C14: 66 | D14: 70 | E14: 51 | F14: 48 | G14: 42
B17: Current 25-vehicle fleet: compliance by demand level
B18: Demand level | C18: Mumbai MMR | D18: Delhi NCR | E18: Bengaluru | F18: Chennai | G18: Kolkata | H18: Target
B19: 0.5 | C19: 0.9728 | D19: 0.9708 | E19: 0.9907 | F19: 1 | G19: 0.9867 | H19: 0.95
B20: 0.75 | C20: 0.9811 | D20: 0.97 | E20: 0.9742 | F20: 1 | G20: 1 | H20: 0.95
B21: 1 | C21: 1 | D21: 0.9474 | E21: 0.986 | F21: 0.9801 | G21: 0.9931 | H21: 0.95
B22: 1.5 | C22: 0.9421 | D22: 0.8025 | E22: 0.9375 | F22: 0.99 | G22: 0.9953 | H22: 0.95
B23: 2 | C23: 0.8288 | D23: 0.6862 | E23: 0.9295 | F23: 0.979 | G23: 0.9899 | H23: 0.95
B24: 3 | C24: 0.6198 | D24: 0.4523 | E24: 0.7406 | F24: 0.848 | G24: 0.9106 | H24: 0.95
B27: All scenarios (per city and all cities)
B28: City | C28: Level | D28: Orders | E28: History days | F28: Current-fleet compliance | G28: Current unassigned | H28: Rec. fleet | I28: Vans | J28: Tempos | K28: 2-wheelers | L28: Rec. compliance | M28: ₹ / order | N28: Duty util % | O28: Annual TCO own ₹ | P28: Annual TCO lease ₹ | Q28: Feasible | R28: Status
B29: All cities | C29: 0.5 | D29: 554 | E29: 11 | F29: 0.9819 | G29: 2 | H29: 61 | I29: 4 | J29: 31 | K29: 26 | L29: 0.9856 | M29: 379.23 | N29: 71 | O29: 48576418 | P29: 51212560 | Q29: Yes | R29: feasible
B30: Mumbai MMR | C30: 0.5 | D30: 147 | E30: 11 | F30: 0.9728 | G30: 0 | H30: 14 | I30: 2 | J30: 6 | K30: 6 | L30: 0.9728 | M30: 343.61 | N30: 74.5 | O30: 12068278 | P30: 12686912 | Q30: Yes | R30: feasible
B31: Delhi NCR | C31: 0.5 | D31: 137 | E31: 11 | F31: 0.9708 | G31: 2 | H31: 16 | I31: 0 | J31: 11 | K31: 5 | L31: 0.9854 | M31: 462.93 | N31: 72.6 | O31: 13497309 | P31: 14263147 | Q31: Yes | R31: feasible
B32: Bengaluru | C32: 0.5 | D32: 107 | E32: 11 | F32: 0.9907 | G32: 0 | H32: 12 | I32: 0 | J32: 6 | K32: 6 | L32: 0.9907 | M32: 343.82 | N32: 68.3 | O32: 8510374 | P32: 8952339 | Q32: Yes | R32: feasible
B33: Chennai | C33: 0.5 | D33: 88 | E33: 11 | F33: 1 | G33: 0 | H33: 11 | I33: 1 | J33: 4 | K33: 6 | L33: 1 | M33: 384.38 | N33: 68.2 | O33: 7951452 | P33: 8299221 | Q33: Yes | R33: feasible
B34: Kolkata | C34: 0.5 | D34: 75 | E34: 11 | F34: 0.9867 | G34: 0 | H34: 8 | I34: 1 | J34: 4 | K34: 3 | L34: 0.9867 | M34: 340.64 | N34: 69.8 | O34: 5830634 | P34: 6292569 | Q34: Yes | R34: feasible
B35: All cities | C35: 0.75 | D35: 832 | E35: 9 | F35: 0.9832 | G35: 3 | H35: 75 | I35: 6 | J35: 45 | K35: 24 | L35: 0.988 | M35: 332.58 | N35: 70.4 | O35: 63825583 | P35: 67763681 | Q35: Yes | R35: feasible
B36: Mumbai MMR | C36: 0.75 | D36: 212 | E36: 9 | F36: 0.9811 | G36: 0 | H36: 18 | I36: 2 | J36: 10 | K36: 6 | L36: 0.9858 | M36: 314.76 | N36: 71.2 | O36: 15627927 | P36: 16564692 | Q36: Yes | R36: feasible
B37: Delhi NCR | C37: 0.75 | D37: 200 | E37: 9 | F37: 0.97 | G37: 3 | H37: 18 | I37: 1 | J37: 12 | K37: 5 | L37: 0.99 | M37: 376.34 | N37: 75.7 | O37: 16429251 | P37: 17338435 | Q37: Yes | R37: feasible
B38: Bengaluru | C38: 0.75 | D38: 155 | E38: 9 | F38: 0.9742 | G38: 0 | H38: 15 | I38: 1 | J38: 9 | K38: 5 | L38: 0.9806 | M38: 339.89 | N38: 67.9 | O38: 12159388 | P38: 12988551 | Q38: Yes | R38: feasible
B39: Chennai | C39: 0.75 | D39: 154 | E39: 9 | F39: 1 | G39: 0 | H39: 13 | I39: 1 | J39: 8 | K39: 4 | L39: 0.9935 | M39: 316.38 | N39: 69.7 | O39: 11268223 | P39: 11873019 | Q39: Yes | R39: feasible
B40: Kolkata | C40: 0.75 | D40: 111 | E40: 9 | F40: 1 | G40: 0 | H40: 11 | I40: 1 | J40: 6 | K40: 4 | L40: 0.991 | M40: 300.07 | N40: 64.5 | O40: 7431014 | P40: 8089203 | Q40: Yes | R40: feasible
... B64: Kolkata | C64: 3 | D64: 481 | E64: 0 | F64: 0.9106 | G64: 42 | H64: 42 | I64: 1 | J64: 27 | K64: 14 | L64: 0.9896 | M64: 240.22 | N64: 52.8 | O64: 24499601 | P64: 27196589 | Q64: Yes | R64: feasible
B67: Annual fleet TCO at 1.0x demand (recommended fleet)
B68: Own = equivalent annual capital cost at WACC + insurance + maintenance + fuel + labour; lease = lease + admin + fuel + labour.
B69: City | C69: Capital (EAC) ₹ | D69: Insurance ₹ | E69: Maintenance ₹ | F69: Fuel ₹ | G69: Labour ₹ | H69: TCO own ₹ | I69: TCO lease ₹
B70: Mumbai MMR | C70: 5033448 | D70: 548000 | E70: 807974 | F70: 4083055 | G70: 9069810 | H70: 19542287 | I70: 20744377
B71: Delhi NCR | C71: 4559745 | D71: 519500 | E71: 964588 | F71: 4914623 | G71: 9388469 | H71: 20346924 | I71: 21459531
...

Sheet Warehouse Slotting
B1: Warehouse Slotting
B2: 10,000-slot DC template per city · velocity zoning + co-pick affinity + ergonomic weight rule
B4: 0.2618 | L4: 0.2335 | V4: 0.2697 | AF4: 3075
B5: Picker travel reduction (held-out) | L5: Pick throughput gain | V5: Perfect-information bound | AF5: Heavy-item slot violations removed · now 0
B7: Mumbai DC pick intensity - Current layout (category order) (rows: bay, columns: aisle; dispatch at top-left)
B8: Bay \ Aisle | C8: 1 | D8: 2 | E8: 3 | F8: 4 | G8: 5 | H8: 6 | I8: 7 | J8: 8 | K8: 9 | L8: 10 | M8: 11 | N8: 12 | O8: 13 | P8: 14 | Q8: 15 | R8: 16 | S8: 17 | T8: 18 | U8: 19 | V8: 20 | W8: 21 | X8: 22 | Y8: 23 | Z8: 24 | AA8: 25 | AB8: 26 | AC8: 27 | AD8: 28 | AE8: 29 | AF8: 30 | AG8: 31 | AH8: 32 | AI8: 33 | AJ8: 34 | AK8: 35 | AL8: 36
B9: 1 | C9: 53.2 | D9: 62.7 | E9: 54.7 | F9: 43.1 | G9: 23.1 | H9: 384.9 | I9: 218.5 | J9: 87.2 | K9: 10.6 | L9: 13.8 | M9: 15.2 | N9: 2.2 | O9: 5.3 | P9: 21.2 | Q9: 15.6 | R9: 35 | S9: 44.6 | T9: 36.9 | U9: 33 | V9: 155.5 | W9: 133.9 | X9: 95.4 | Y9: 87.4 | Z9: 29.3 | AA9: 162 | AB9: 6.5 | AC9: 8.1 | AD9: 8.6 | AE9: 8.3 | AF9: 24.5 | AG9: 75.3 | AH9: 7 | AI9: 23.8 | AJ9: 21.8 | AK9: 29.8 | AL9: 52.3
B10: 2 | C10: 34.8 | D10: 17 | E10: 77.9 | F10: 60.1 | G10: 15.8 | H10: 123.9 | I10: 321.5 | J10: 126.2 | K10: 10.6 | L10: 17.2 | M10: 16.2 | N10: 4.6 | O10: 12.5 | P10: 65.3 | Q10: 29.2 | R10: 39.4 | S10: 11 | T10: 76.1 | U10: 23.4 | V10: 27.8 | W10: 203 | X10: 256.6 | Y10: 78.5 | Z10: 57.3 | AA10: 79.9 | AB10: 5.4 | AC10: 8.9 | AD10: 19.3 | AE10: 14.7 | AF10: 34.9 | AG10: 84.8 | AH10: 9.5 | AI10: 15.3 | AJ10: 36.8 | AK10: 16.4 | AL10: 40.3
B11: 3 | C11: 65.2 | D11: 13.8 | E11: 45.9 | F11: 20.2 | G11: 21.9 | H11: 124.1 | I11: 568.7 | J11: 111 | K11: 38.8 | L11: 13.7 | M11: 33.8 | N11: 278.1 | O11: 7.7 | P11: 102.7 | Q11: 71.5 | R11: 98 | S11: 41.9 | T11: 68.9 | U11: 21.9 | V11: 7.2 | W11: 42.4 | X11: 442.8 | Y11: 82.3 | Z11: 75.5 | AA11: 108.7 | AB11: 8.6 | AC11: 28.3 | AD11: 24.9 | AE11: 11.5 | AF11: 51.6 | AG11: 38.4 | AH11: 10.3 | AI11: 15.1 | AJ11: 234.6 | AK11: 8 | AL11: 76.3
B12: 4 | C12: 37.1 | D12: 21.3 | E12: 204.3 | F12: 17 | G12: 51 | H12: 120.1 | I12: 307.9 | J12: 85.5 | K12: 43.1 | L12: 14.5 | M12: 46.5 | N12: 2917 | O12: 13.3 | P12: 244.3 | Q12: 91.6 | R12: 72 | S12: 23.4 | T12: 41.3 | U12: 121.3 | V12: 12.8 | W12: 35.9 | X12: 319.8 | Y12: 72.7 | Z12: 124.3 | AA12: 118.6 | AB12: 45.4 | AC12: 73.1 | AD12: 8.5 | AE12: 13.5 | AF12: 126.2 | AG12: 20.2 | AH12: 288.7 | AI12: 19.1 | AJ12: 169.3 | AK12: 19.2 | AL12: 169.4
B13: 5 | C13: 1.8 | D13: 49 | E13: 23.6 | F13: 22.6 | G13: 72.2 | H13: 36.9 | I13: 11 | J13: 121.7 | K13: 20.7 | L13: 34.4 | M13: 47.1 | N13: 1551.4 | O13: 19.3 | P13: 69.1 | Q13: 69.2 | R13: 129.8 | S13: 13.1 | T13: 123.7 | U13: 40.5 | V13: 20.8 | W13: 105.5 | X13: 45.3 | Y13: 99.6 | Z13: 828.3 | AA13: 178.2 | AB13: 40.5 | AC13: 22.1 | AD13: 8.5 | AE13: 8.7 | AF13: 60.6 | AG13: 6 | AH13: 571.1 | AI13: 28.7 | AJ13: 396.2 | AK13: 12 | AL13: 173.1
B14: 6 | C14: 18.8 | D14: 73.3 | E14: 1 | F14: 7.9 | G14: 157 | H14: 80 | I14: 23.8 | J14: 46.7 | K14: 34.8 | L14: 31.9 | M14: 19.1 | N14: 4514.6 | O14: 16.9 | P14: 32 | Q14: 1 | R14: 75.4 | S14: 216.2 | T14: 9.1 | U14: 19.6 | V14: 28.1 | W14: 69.1 | X14: 57.3 | Y14: 135.3 | Z14: 202 | AA14: 351.8 | AB14: 24.5 | AC14: 12.3 | AD14: 13.4 | AE14: 21 | AF14: 58.3 | AG14: 10.8 | AH14: 234.3 | AI14: 40.3 | AJ14: 230.6 | AK14: 140.7 | AL14: 192.3
B15: 7 | C15: 26.7 | D15: 36.9 | E15: 1.3 | F15: 32.7 | G15: 29.7 | H15: 52.4 | I15: 24.6 | J15: 36.6 | K15: 81.2 | L15: 20 | M15: 33.4 | N15: 121.4 | O15: 72.1 | P15: 33.6 | Q15: 1 | R15: 61 | S15: 431.7 | T15: 2.7 | U15: 27.6 | V15: 14.6 | W15: 112.8 | X15: 51.7 | Y15: 215.3 | Z15: 303.5 | AA15: 5.5 | AB15: 55.7 | AC15: 19.5 | AD15: 9.7 | AE15: 7.5 | AF15: 33.8 | AG15: 29.2 | AH15: 142 | AI15: 38.9 | AJ15: 61.5 | AK15: 167.2 | AL15: 63.1
B16: 8 | C16: 51.5 | D16: 49.7 | E16: 13.2 | F16: 128.9 | G16: 28.8 | H16: 56.6 | I16: 57 | J16: 51 | K16: 42.7 | L16: 15.9 | M16: 152.3 | N16: 36.6 | O16: 33.5 | P16: 63.8 | Q16: 15.8 | R16: 51.6 | S16: 187.8 | T16: 7 | U16: 62.3 | V16: 33.7 | W16: 84.3 | X16: 83.2 | Y16: 94.8 | Z16: 707.5 | AA16: 9.5 | AB16: 48.5 | AC16: 12.9 | AD16: 8.1 | AE16: 10.7 | AF16: 37 | AG16: 81.3 | AH16: 22.6 | AI16: 19.7 | AJ16: 15.1 | AK16: 176.8 | AL16: 58.7
B17: 9 | C17: 239.9 | D17: 29.4 | E17: 14 | F17: 26.9 | G17: 34 | H17: 65.4 | I17: 59.4 | J17: 51.8 | K17: 18.9 | L17: 9.5 | M17: 87.5 | N17: 29.6 | O17: 81.6 | P17: 91.6 | Q17: 71.6 | R17: 61.5 | S17: 40.2 | T17: 53 | U17: 28.3 | V17: 88.1 | W17: 103.6 | X17: 188.9 | Y17: 68.4 | Z17: 124.1 | AA17: 8.7 | AB17: 22.5 | AC17: 5.3 | AD17: 19.1 | AE17: 135.3 | AF17: 90.9 | AG17: 66.9 | AH17: 17.8 | AI17: 8.1 | AJ17: 60.3 | AK17: 199.9 | AL17: 13.1
B18: 10 | C18: 109.5 | D18: 19.4 | E18: 8.4 | F18: 72.5 | G18: 9.2 | H18: 256.2 | I18: 16 | J18: 160.1 | K18: 22.9 | L18: 42.2 | M18: 99.1 | N18: 27.7 | O18: 63.9 | P18: 41.1 | Q18: 103.4 | R18: 147.1 | S18: 29 | T18: 61 | U18: 85.1 | V18: 67.8 | W18: 148.9 | X18: 252.9 | Y18: 13.2 | Z18: 248.5 | AA18: 6.3 | AB18: 16.4 | AC18: 20.3 | AD18: 7.3 | AE18: 139.8 | AF18: 91.9 | AG18: 219.7 | AH18: 117.2 | AI18: 17.7 | AJ18: 35.3 | AK18: 111.8 | AL18: 103.3
B19: 11 | C19: 111.9 | D19: 138.4 | E19: 6 | F19: 113.1 | G19: 67.7 | H19: 467.4 | I19: 4.3 | J19: 290.9 | K19: 10.2 | L19: 55.6 | M19: 123.1 | N19: 50.9 | O19: 17.4 | P19: 56 | Q19: 79.1 | R19: 263.8 | S19: 45.8 | T19: 225.8 | U19: 70 | V19: 309.5 | W19: 14.2 | X19: 213.7 | Y19: 88.6 | Z19: 92.9 | AA19: 46 | AB19: 56.9 | AC19: 19.2 | AD19: 11.3 | AE19: 73.4 | AF19: 22.1 | AG19: 54.4 | AH19: 189.3 | AI19: 6.3 | AJ19: 28.9 | AK19: 171.8 | AL19: 38.1
B20: 12 | C20: 11.6 | D20: 45.4 | E20: 79.1 | F20: 188.2 | G20: 81.8 | H20: 360.7 | I20: 9.4 | J20: 116.1 | K20: 15.5 | L20: 101.7 | M20: 55.3 | N20: 28 | O20: 20.6 | P20: 51.6 | Q20: 275.1 | R20: 238.4 | S20: 131.5 | T20: 150.6 | U20: 208.6 | V20: 373.5 | W20: 33.4 | X20: 359.3 | Y20: 75.8 | Z20: 64.4 | AA20: 106.2 | AB20: 17.3 | AC20: 22.4 | AD20: 34.2 | AE20: 69.9 | AF20: 26.9 | AG20: 104.8 | AH20: 405.4 | AI20: 6 | AJ20: 26.2 | AK20: 67.7 | AL20: 54.9
... B28: 20 | C28: 30.9 | D28: 17.5 | E28: 88.5 | F28: 96.1 | G28: 62 | H28: 166.4 | I28: 16.5 | J28: 17.6 | K28: 113.4 | L28: 12.6 | M28: 13.3 | N28: 30 | O28: 101.6 | P28: 21.9 | Q28: 61.3 | R28: 9.9 | S28: 15.2 | T28: 40.1 | U28: 47.1 | V28: 10.4 | W28: 45.2 | X28: 45.9 | Y28: 35.9 | Z28: 25 | AA28: 96.7 | AB28: 52.7 | AC28: 13.1 | AD28: 41.5 | AE28: 35.2 | AF28: 23.4 | AG28: 153.1 | AH28: 402.5 | AI28: 65.5 | AJ28: 153.2 | AK28: 4.4 | AL28: 8.4
B31: Mumbai DC pick intensity - Optimized layout (rows: bay, columns: aisle; dispatch at top-left)
B32: Bay \ Aisle | C32: 1 | D32: 2 | E32: 3 | F32: 4 | G32: 5 | H32: 6 | I32: 7 | J32: 8 | K32: 9 | L32: 10 | M32: 11 | N32: 12 | O32: 13 | P32: 14 | Q32: 15 | R32: 16 | S32: 17 | T32: 18 | U32: 19 | V32: 20 | W32: 21 | X32: 22 | Y32: 23 | Z32: 24 | AA32: 25 | AB32: 26 | AC32: 27 | AD32: 28 | AE32: 29 | AF32: 30 | AG32: 31 | AH32: 32 | AI32: 33 | AJ32: 34 | AK32: 35 | AL32: 36
B33: 1 | C33: 6311.4 | D33: 146.5 | E33: 165.8 | F33: 503.7 | G33: 273.2 | H33: 261.7 | I33: 435.8 | J33: 302.9 | K33: 131.9 | L33: 144.9 | M33: 166.9 | N33: 83.1 | O33: 79.5 | P33: 70.8 | Q33: 36.4 | R33: 31.3 | S33: 28.9 | T33: 48.6 | U33: 47.8 | V33: 31.3 | W33: 30.9 | X33: 22.4 | Y33: 22.2 | Z33: 17.3 | AA33: 17.1 | AB33: 12.8 | AC33: 12.7 | AD33: 10.2 | AE33: 10.2 | AF33: 8.5 | AG33: 8.4 | AH33: 6.4 | AI33: 6.3 | AJ33: 6.1 | AK33: 2.2 | AL33: 0.2
B34: 2 | C34: 1566.2 | D34: 252 | E34: 572.3 | F34: 139.4 | G34: 115.6 | H34: 118.7 | I34: 422.1 | J34: 136.3 | K34: 245.7 | L34: 174.5 | M34: 112.4 | N34: 87.2 | O34: 75.8 | P34: 30.5 | Q34: 39.9 | R34: 34.7 | S34: 37.2 | T34: 44.2 | U34: 47 | V34: 31.8 | W34: 30.5 | X34: 22.6 | Y34: 22.2 | Z34: 17.5 | AA34: 17 | AB34: 12.8 | AC34: 12.7 | AD34: 10.3 | AE34: 10.1 | AF34: 8.6 | AG34: 8.2 | AH34: 6.5 | AI34: 6.2 | AJ34: 2.3 | AK34: 2.2 | AL34: 0.2
B35: 3 | C35: 1352 | D35: 218.8 | E35: 472.5 | F35: 505.7 | G35: 431.8 | H35: 219.7 | I35: 189.6 | J35: 260.3 | K35: 113.5 | L35: 170.8 | M35: 137.7 | N35: 91.1 | O35: 74.4 | P35: 33.1 | Q35: 29.1 | R35: 36.9 | S35: 37.7 | T35: 44.8 | U35: 46.4 | V35: 32 | W35: 30.1 | X35: 22.8 | Y35: 22 | Z35: 17.6 | AA35: 16.9 | AB35: 13 | AC35: 12.6 | AD35: 10.4 | AE35: 10.1 | AF35: 8.6 | AG35: 8 | AH35: 6.6 | AI35: 6.1 | AJ35: 2.4 | AK35: 2.1 | AL35: 0.2
B36: 4 | C36: 732.4 | D36: 304 | E36: 223.9 | F36: 329.1 | G36: 165.6 | H36: 288.1 | I36: 294.8 | J36: 127.8 | K36: 78.4 | L36: 147.6 | M36: 110.5 | N36: 95.6 | O36: 73.1 | P36: 40.8 | Q36: 36 | R36: 34.3 | S36: 32.1 | T36: 51 | U36: 45.6 | V36: 32.3 | W36: 29.8 | X36: 23 | Y36: 21.8 | Z36: 17.8 | AA36: 16.7 | AB36: 13 | AC36: 12.4 | AD36: 10.5 | AE36: 10 | AF36: 8.6 | AG36: 7.9 | AH36: 6.8 | AI36: 6.1 | AJ36: 2.4 | AK36: 2.1 | AL36: 0.2
B37: 5 | C37: 462.3 | D37: 438.4 | E37: 223.8 | F37: 119.9 | G37: 120.4 | H37: 293.8 | I37: 148.7 | J37: 269.9 | K37: 269.7 | L37: 160.4 | M37: 126.3 | N37: 103.2 | O37: 44.4 | P37: 46.5 | Q37: 35 | R37: 28.7 | S37: 29.1 | T37: 51.6 | U37: 42.3 | V37: 32.5 | W37: 29.5 | X37: 23.1 | Y37: 21.6 | Z37: 17.9 | AA37: 16.5 | AB37: 13.1 | AC37: 12.4 | AD37: 10.5 | AE37: 10 | AF37: 8.8 | AG37: 7.7 | AH37: 6.8 | AI37: 4.1 | AJ37: 2.5 | AK37: 2.1 | AL37: 0.3
B38: 6 | C38: 136.5 | D38: 860.7 | E38: 129.7 | F38: 271.3 | G38: 211.9 | H38: 357.3 | I38: 90.3 | J38: 114.6 | K38: 89.1 | L38: 113.5 | M38: 124.1 | N38: 115.7 | O38: 41.1 | P38: 33.2 | Q38: 40.9 | R38: 32.7 | S38: 31.4 | T38: 43.6 | U38: 44.5 | V38: 32.6 | W38: 29.3 | X38: 23.4 | Y38: 21.5 | Z38: 18.1 | AA38: 16.5 | AB38: 13.2 | AC38: 12.3 | AD38: 10.6 | AE38: 9.9 | AF38: 8.9 | AG38: 7.6 | AH38: 7 | AI38: 3.9 | AJ38: 2.5 | AK38: 2 | AL38: 0.4
B39: 7 | C39: 157.3 | D39: 110.1 | E39: 201.9 | F39: 417.6 | G39: 469.3 | H39: 187.2 | I39: 306.9 | J39: 168 | K39: 253.3 | L39: 173.9 | M39: 99 | N39: 41.1 | O39: 32.7 | P39: 43.4 | Q39: 38.1 | R39: 23 | S39: 35 | T39: 53.6 | U39: 43.8 | V39: 32.7 | W39: 29.2 | X39: 23.7 | Y39: 21.4 | Z39: 18.2 | AA39: 16.3 | AB39: 13.3 | AC39: 12.3 | AD39: 10.6 | AE39: 9.9 | AF39: 9 | AG39: 7.5 | AH39: 4.1 | AI39: 3.8 | AJ39: 2.6 | AK39: 2 | AL39: 0.6
B40: 8 | C40: 100 | D40: 108 | E40: 109.8 | F40: 222.3 | G40: 148.5 | H40: 551.3 | I40: 155.6 | J40: 112.1 | K40: 115.7 | L40: 208.6 | M40: 117.7 | N40: 51.2 | O40: 46.4 | P40: 41.1 | Q40: 34.7 | R40: 34.1 | S40: 27.3 | T40: 56.1 | U40: 43.1 | V40: 33.1 | W40: 29 | X40: 23.9 | Y40: 21.2 | Z40: 18.3 | AA40: 16.2 | AB40: 13.3 | AC40: 12.2 | AD40: 10.7 | AE40: 9.9 | AF40: 9.1 | AG40: 7.3 | AH40: 4.2 | AI40: 3.8 | AJ40: 2.6 | AK40: 1.9 | AL40: 0.7
B41: 9 | C41: 1212.4 | D41: 122.3 | E41: 84.9 | F41: 690.7 | G41: 509.2 | H41: 113.1 | I41: 91.3 | J41: 242.7 | K41: 231.3 | L41: 191.9 | M41: 91.5 | N41: 36.9 | O41: 40 | P41: 39.9 | Q41: 32.7 | R41: 36.4 | S41: 31.8 | T41: 48.2 | U41: 42.5 | V41: 33.4 | W41: 28.9 | X41: 24 | Y41: 21.1 | Z41: 18.5 | AA41: 16 | AB41: 13.4 | AC41: 12.2 | AD41: 10.8 | AE41: 9.9 | AF41: 9.1 | AG41: 7.2 | AH41: 4.2 | AI41: 3.8 | AJ41: 2.6 | AK41: 1.9 | AL41: 0.8
B42: 10 | C42: 852.8 | D42: 176.5 | E42: 844.9 | F42: 100.4 | G42: 209.4 | H42: 192.6 | I42: 394 | J42: 98.7 | K42: 109.5 | L42: 148 | M42: 38.9 | N42: 38.4 | O42: 54.5 | P42: 46.2 | Q42: 41.8 | R42: 39.9 | S42: 33.3 | T42: 48.4 | U42: 41.5 | V42: 33.6 | W42: 28.6 | X42: 24.2 | Y42: 21 | Z42: 18.6 | AA42: 15.9 | AB42: 13.4 | AC42: 12.1 | AD42: 10.8 | AE42: 9.7 | AF42: 9.3 | AG42: 4.2 | AH42: 3.4 | AI42: 3.7 | AJ42: 2.6 | AK42: 1.9 | AL42: 0.8
B43: 11 | C43: 442.7 | D43: 159.6 | E43: 342.6 | F43: 190.3 | G43: 109.2 | H43: 451.8 | I43: 161.1 | J43: 242.6 | K43: 272 | L43: 192.6 | M43: 46.1 | N43: 44.6 | O43: 42.4 | P43: 33 | Q43: 39.2 | R43: 28.4 | S43: 27.2 | T43: 47.7 | U43: 41.2 | V43: 33.7 | W43: 28.3 | X43: 24.4 | Y43: 20.8 | Z43: 18.7 | AA43: 15.8 | AB43: 13.5 | AC43: 12.1 | AD43: 10.9 | AE43: 9.6 | AF43: 9.3 | AG43: 4.1 | AH43: 2.6 | AI43: 3.7 | AJ43: 2.7 | AK43: 1.9 | AL43: 0.9
B44: 12 | C44: 303.7 | D44: 271 | E44: 192.4 | F44: 609.6 | G44: 514.7 | H44: 84.8 | I44: 89 | J44: 109.3 | K44: 168.1 | L44: 38.4 | M44: 58.9 | N44: 46.9 | O44: 47.3 | P44: 45 | Q44: 35.1 | R44: 31.7 | S44: 28.9 | T44: 57.9 | U44: 41 | V44: 34.2 | W44: 28.1 | X44: 24.5 | Y44: 20.6 | Z44: 18.8 | AA44: 15.7 | AB44: 13.6 | AC44: 11.9 | AD44: 11 | AE44: 9.5 | AF44: 4.3 | AG44: 4.1 | AH44: 2.7 | AI44: 3.7 | AJ44: 2.8 | AK44: 1.9 | AL44: 0.9
... B52: 20 | C52: 229.1 | D52: 111.1 | E52: 575.9 | F52: 312 | G52: 79.2 | H52: 432.3 | I52: 63.9 | J52: 49.7 | K52: 50.6 | L52: 49.6 | M52: 46.5 | N52: 49.6 | O52: 29.9 | P52: 43.8 | Q52: 31.4 | R52: 33.3 | S52: 19.2 | T52: 25.6 | U52: 33.3 | V52: 36.6 | W52: 26.4 | X52: 26.2 | Y52: 19.7 | Z52: 19.7 | AA52: 14.5 | AB52: 14.5 | AC52: 6 | AD52: 5.7 | AE52: 4.9 | AF52: 4.8 | AG52: 3.5 | AH52: 3.4 | AI52: 3.1 | AJ52: 3.1 | AK52: 1.4 | AL52: 1.4

Sheet Warehouse Performance
B1: Warehouse Performance
B2: Held-out pick orders · return routing, batches of 3 · labour cost at city wage level
B4: Current vs optimized vs perfect-information bound (formulas)
B5: City | C5: Pick lines | D5: Travel m/line (current) | E5: Travel m/line (optimized) | F5: Travel m/line (bound) | G5: Travel reduction | H5: Picks/h (current) | I5: Picks/h (optimized) | J5: Picks/h (bound) | K5: Throughput gain | L5: ₹/1,000 picks (current) | M5: ₹/1,000 picks (optimized) | N5: Labour saving | O5: Heavy violations (current) | P5: Heavy violations (optimized) | Q5: Bound captured
B6: Mumbai MMR | C6: 34385 | D6: 35.35 | E6: 25.85 | F6: 25.68 | G6: =1-E6/D6 | H6: 62.5 | I6: 77.4 | J6: 77.7 | K6: =I6/H6-1 | L6: 2958.1 | M6: 2390.5 | N6: =1-M6/L6 | O6: 615 | P6: 0 | Q6: =(D6-E6)/(D6-F6)
B7: Delhi NCR | C7: 36416 | D7: 35.24 | E7: 25.57 | F7: 25.66 | G7: =1-E7/D7 | H7: 62.6 | I7: 77.9 | J7: 78.1 | K7: =I7/H7-1 | L7: 2956.8 | M7: 2373.5 | N7: =1-M7/L7 | O7: 615 | P7: 0 | Q7: =(D7-E7)/(D7-F7)
B8: Bengaluru | C8: 29702 | D8: 35.76 | E8: 26.58 | F8: 26.06 | G8: =1-E8/D8 | H8: 62 | I8: 76.2 | J8: 77.1 | K8: =I8/H8-1 | L8: 3042.5 | M8: 2476.2 | N8: =1-M8/L8 | O8: 615 | P8: 0 | Q8: =(D8-E8)/(D8-F8)
B9: Chennai | C9: 24209 | D9: 34.7 | E9: 25.85 | F9: 25.36 | G9: =1-E9/D9 | H9: 63.3 | I9: 77.5 | J9: 78.4 | K9: =I9/H9-1 | L9: 2690.8 | M9: 2195 | N9: =1-M9/L9 | O9: 615 | P9: 0 | Q9: =(D9-E9)/(D9-F9)
B10: Kolkata | C10: 20811 | D10: 36.54 | E10: 27.63 | F10: 27.09 | G10: =1-E10/D10 | H10: 61 | I10: 74.5 | J10: 75.2 | K10: =I10/H10-1 | L10: 2579.6 | M10: 2111.4 | N10: =1-M10/L10 | O10: 615 | P10: 0 | Q10: =(D10-E10)/(D10-F10)
B11: All cities (line-weighted) | G11: =1-SUMPRODUCT(E6:E10,$C$6:$C$10)/SUMPRODUCT(D6:D10,$C$6:$C$10) | K11: =SUMPRODUCT(I6:I10,$C$6:$C$10)/SUMPRODUCT(H6:H10,$C$6:$C$10)-1
B30: Targets: 35% less picker travel and 25-30% more throughput. Measured gains sit within ~1-2 points of the perfect-information bound (same method fed each SKU's long-run demand rate), so the shortfall is a property of this SKU profile and return-routing batch picking, not of the slotting method. Reaching the targets would need a different picking policy (e.g. zone or wave picking with S-shape routing) - outside slotting scope.
B33: Share of training picks by zone after slotting | J33: Velocity shrinkage chosen by internal validation (travel m)
B34: Zone A holds 20% of slots nearest dispatch; velocity zoning concentrates picks there.
B35: City | C35: Zone A (golden) | D35: Zone B | E35: Zone C (bulk) | J35: Shrinkage k | K35: Mumbai MMR | L35: Delhi NCR | M35: Bengaluru | N35: Chennai | O35: Kolkata
B36: Mumbai MMR | C36: 0.8368 | D36: 0.1581 | E36: 0.005 | J36: 0 | K36: 461138.2 | L36: 476099 | M36: 391463.6 | N36: 321536.2 | O36: 301049.2
B37: Delhi NCR | C37: 0.8322 | D37: 0.1628 | E37: 0.005 | J37: 0.25 | K37: 452605.8 | L37: 471973.4 | M37: 385772 | N37: 312536 | O37: 292606.6
B38: Bengaluru | C38: 0.7995 | D38: 0.1926 | E38: 0.0079 | J38: 0.5 | K38: 456001 | L38: 472216.2 | M38: 385150.2 | N38: 316844.2 | O38: 293492.8
B39: Chennai | C39: 0.8371 | D39: 0.1588 | E39: 0.0041 | J39: 1 | K39: 458802.8 | L39: 475554.6 | M39: 391869.4 | N39: 318358.8 | O39: 292694
B40: Kolkata | C40: 0.8241 | D40: 0.1715 | E40: 0.0044

Sheet Simulation Results
B1: Simulation Results
B2: SimPy DC model per city · 200 Monte Carlo replications per scenario · target P95 intake-to-dispatch <= 120 min
B4: Pooled P95 cycle time (minutes) by scenario
B5: City | C5: Baseline staffing | D5: Optimized staffing | E5: Diwali peak - baseline staffing | F5: Diwali peak - peak roster | G5: Target
B6: Mumbai MMR | C6: 171.31123 | D6: 98.191823 | E6: 457.91407 | F6: 114.4796 | G6: 120
B7: Delhi NCR | C7: 145.59246 | D7: 88.350819 | E7: 432.51083 | F7: 97.118887 | G7: 120
B8: Bengaluru | C8: 100.67712 | D8: 102.43752 | E8: 351.14754 | F8: 87.310196 | G8: 120
B9: Chennai | C9: 306.82239 | D9: 88.994409 | E9: 543.31957 | F9: 106.1326 | G9: 120
B10: Kolkata | C10: 164.10401 | D10: 106.231 | E10: 518.97713 | F10: 100.73761 | G10: 120
B24: Scenario detail (P10 / P50 / P90 across replications)
B25: City | C25: Scenario | D25: Roster | E25: Staff ₹/day | F25: Throughput P10 | G25: Throughput P50 | H25: Throughput P90 | I25: P95 cycle P10 | J25: P95 cycle P50 | K25: P95 cycle P90 | L25: Pooled P95 | M25: SLA share P50 | N25: Backlog P50 | O25: Picker util | P25: Packer util | Q25: Loader util | R25: Bottleneck | S25: Meets target
B26: Mumbai MMR | C26: Baseline staffing | D26: 5/3/1/2 | E26: 32000 | F26: 263 | G26: 281 | H26: 306.1 | I26: 115.30447 | J26: 147.58263 | K26: 183.95352 | L26: 171.31123 | M26: 0.63431979 | N26: 0 | O26: 0.4285 | P26: 0.6347 | Q26: 0.5902 | R26: packers | S26: No
B27: Mumbai MMR | C27: Optimized staffing | D27: 5/4/1/3 | E27: 37500 | F27: 258 | G27: 283 | H27: 305 | I27: 71.621918 | J27: 86.467299 | K27: 110.90676 | L27: 98.191823 | M27: 1 | N27: 0 | O27: 0.4274 | P27: 0.4768 | Q27: 0.3914 | R27: packers | S27: Yes
B28: Mumbai MMR | C28: Diwali peak - baseline staffing | D28: 5/3/1/2 | E28: 32000 | F28: 370 | G28: 379 | H28: 390 | I28: 419.62748 | J28: 450.66397 | K28: 483.65434 | L28: 457.91407 | M28: 0.16060549 | N28: 176 | O28: 0.7257 | P28: 0.8386 | Q28: 0.7907 | R28: packers | S28: No
B29: Mumbai MMR | C29: Diwali peak - peak roster | D29: 7/7/1/5 | E29: 57220 | F29: 525.9 | G29: 555 | H29: 584 | I29: 84.529687 | J29: 102.13689 | K29: 125.90588 | L29: 114.4796 | M29: 0.99242424 | N29: 0 | O29: 0.5254 | P29: 0.5228 | Q29: 0.4627 | R29: pickers | S29: Yes
B30: Delhi NCR | C30: Baseline staffing | D30: 5/3/1/2 | E30: 32000 | F30: 249.9 | G30: 268 | H30: 285.1 | I30: 99.437808 | J30: 130.33457 | K30: 155.12945 | L30: 145.59246 | M30: 0.88245074 | N30: 0 | O30: 0.4115 | P30: 0.6047 | Q30: 0.5593 | R30: packers | S30: No
B31: Delhi NCR | C31: Optimized staffing | D31: 5/4/1/3 | E31: 37500 | F31: 241 | G31: 267 | H31: 290 | I31: 66.829204 | J31: 78.294146 | K31: 99.514357 | L31: 88.350819 | M31: 1 | N31: 0 | O31: 0.4108 | P31: 0.4518 | Q31: 0.3704 | R31: packers | S31: Yes
B32: Delhi NCR | C32: Diwali peak - baseline staffing | D32: 5/3/1/2 | E32: 32000 | F32: 373.9 | G32: 382 | H32: 392 | I32: 398.28381 | J32: 424.96126 | K32: 455.85266 | L32: 432.51083 | M32: 0.17574111 | N32: 142 | O32: 0.6504 | P32: 0.8385 | Q32: 0.796 | R32: packers | S32: No
B33: Delhi NCR | C33: Diwali peak - peak roster | D33: 7/7/1/5 | E33: 57220 | F33: 497 | G33: 523 | H33: 552.1 | I33: 72.659942 | J33: 87.265884 | K33: 106.83856 | L33: 97.118887 | M33: 1 | N33: 0 | O33: 0.4618 | P33: 0.489 | Q33: 0.4371 | R33: packers | S33: Yes
B34: Bengaluru | C34: Baseline staffing | D34: 4/3/1/2 | E34: 29621 | F34: 196 | G34: 215 | H34: 233 | I34: 73.200323 | J34: 88.715062 | K34: 112.12402 | L34: 100.67712 | M34: 1 | N34: 0 | O34: 0.417 | P34: 0.485 | Q34: 0.4481 | R34: packers | S34: Yes
B35: Bengaluru | C35: Optimized staffing | D35: 4/3/1/2 | E35: 29621 | F35: 195 | G35: 213 | H35: 232.1 | I35: 71.490346 | J35: 86.816546 | K35: 113.26417 | L35: 102.43752 | M35: 1 | N35: 0 | O35: 0.4212 | P35: 0.4833 | Q35: 0.4453 | R35: packers | S35: Yes
B36: Bengaluru | C36: Diwali peak - baseline staffing | D36: 4/3/1/2 | E36: 29621 | F36: 366 | G36: 377.5 | H36: 388.1 | I36: 313.8749 | J36: 349.99936 | K36: 374.24135 | L36: 351.14754 | M36: 0.22738044 | N36: 54 | O36: 0.6975 | P36: 0.8291 | Q36: 0.7856 | R36: packers | S36: No
B37: Bengaluru | C37: Diwali peak - peak roster | D37: 6/6/1/4 | E37: 49735 | F37: 406.8 | G37: 429 | H37: 457.2 | I37: 68.057632 | J37: 79.525719 | K37: 95.882548 | L37: 87.310196 | M37: 1 | N37: 0 | O37: 0.4622 | P37: 0.4695 | Q37: 0.4476 | R37: packers | S37: Yes
... B45: Kolkata | C45: Diwali peak - peak roster | D45: 5/5/1/3 | E45: 34255 | F45: 328 | G45: 347 | H45: 373.1 | I45: 73.9798 | J45: 90.819793 | K45: 112.49023 | L45: 100.73761 | M45: 1 | N45: 0 | O45: 0.4639 | P45: 0.4573 | Q45: 0.483 | R45: loaders | S45: Yes
B48: Mumbai DC: distribution of intake-to-dispatch time (all replications)
B49: Cycle bin (min) | C49: Baseline staffing | D49: Optimized staffing | E49: Diwali peak - baseline staffing | F49: Diwali peak - peak roster
B50: 0 | C50: 33 | D50: 58 | E50: 27 | F50: 110
B51: 10 | C51: 445 | D51: 1066 | E51: 491 | F51: 1535
B52: 20 | C52: 1400 | D52: 4368 | E52: 1008 | F52: 4390
B53: 30 | C53: 2868 | D53: 10773 | E53: 2307 | F53: 13517
B54: 40 | C54: 3098 | D54: 10639 | E54: 2407 | F54: 14968
B55: 50 | C55: 3048 | D55: 9056 | E55: 2088 | F55: 14758
B56: 60 | C56: 3180 | D56: 6991 | E56: 1850 | F56: 14316
B57: 70 | C57: 3424 | D57: 5336 | E57: 1666 | F57: 13675
B58: 80 | C58: 4049 | D58: 3481 | E58: 1587 | F58: 11501
B59: 90 | C59: 4559 | D59: 2187 | E59: 1528 | F59: 8710
B60: 100 | C60: 4829 | D60: 1304 | E60: 1421 | F60: 6115
B61: 110 | C61: 4961 | D61: 668 | E61: 1461 | F61: 3692
... B97: 470 | C97: 0 | D97: 0 | E97: 2214 | F97: 0

Sheet Network Design
B1: Network Design
B2: p-median (PuLP) over candidate MFC sites per city · 2-hour SLA tested at evening-peak traffic
B4: Cross-state MFC investment ranking (lowest break-even volume first)
B5: Priority | C5: City | D5: State(s) | E5: Parcels/day | F5: 2h SLA today | G5: Best p | H5: Best sites | I5: Best NPV (₹ cr) | J5: Break-even parcels/day | K5: Break-even x volume | L5: Min p for 100% SLA | M5: ₹ / order-km | N5: Recommendation
B6: 1 | C6: Delhi NCR | D6: Delhi / Haryana / Uttar Pradesh | E6: 193.9 | F6: 0.4189 | G6: 1 | H6: Mayapuri | I6: -2.7129032 | J6: 551 | K6: 2.84 | L6: 3 | M6: 7.82 | N6: Defer new MFCs: no configuration has positive NPV at today's 194 parcels/day. Least-negative option p=1 (Mayapuri) breaks even at 2.8x volume (~551 parcels/day).
B7: 2 | C7: Mumbai MMR | D7: Maharashtra | E7: 183.6 | F7: 0.7603 | G7: 1 | H7: Byculla | I7: -4.4249197 | J7: 1131 | K7: 6.16 | L7: 2 | M7: 8.66 | N7: Defer new MFCs: no configuration has positive NPV at today's 184 parcels/day. Least-negative option p=1 (Byculla) breaks even at 6.2x volume (~1131 parcels/day).
B8: 3 | C8: Kolkata | D8: West Bengal | E8: 106.5 | F8: 0.9811 | G8: 1 | H8: Park Circus | I8: -3.3202547 | J8: 673 | K8: 6.32 | L8: 1 | M8: 10.52 | N8: Defer new MFCs: no configuration has positive NPV at today's 106 parcels/day. Least-negative option p=1 (Park Circus) breaks even at 6.3x volume (~673 parcels/day).
B9: 4 | C9: Bengaluru | D9: Karnataka | E9: 154.1 | F9: 0.9327 | G9: 1 | H9: Hebbal | I9: -3.4995517 | J9: 1303 | K9: 8.46 | M9: 11.75 | N9: Defer new MFCs: no configuration has positive NPV at today's 154 parcels/day. Least-negative option p=1 (Hebbal) breaks even at 8.5x volume (~1303 parcels/day).
B10: 5 | C10: Chennai | D10: Tamil Nadu | E10: 126.9 | F10: 0.8994 | G10: 1 | H10: Kolathur | I10: -3.1325883 | J10: 1445 | K10: 11.39 | M10: 8.64 | N10: Defer new MFCs: no configuration has positive NPV at today's 127 parcels/day. Least-negative option p=1 (Kolathur) breaks even at 11.4x volume (~1445 parcels/day).
B13: Average last-mile km per parcel vs number of new MFCs
B14: New MFCs (p) | C14: Mumbai MMR | D14: Delhi NCR | E14: Bengaluru | F14: Chennai | G14: Kolkata
B15: 0 | C15: 11.89 | D15: 18.77 | E15: 9.75 | F15: 10.11 | G15: 9.88
B16: 1 | C16: 8.39 | D16: 12.46 | E16: 8.07 | F16: 8.33 | G16: 6.26
B17: 2 | C17: 5.82 | D17: 7.97 | E17: 6.58 | F17: 7.03 | G17: 5.19
B18: 3 | C18: 5.27 | D18: 6.56 | E18: 5.84 | F18: 5.79 | G18: 4.48
B19: 4 | C19: 4.77 | D19: 5.29 | E19: 5.2 | F19: 4.83 | G19: 3.93
B20: 5 | C20: 4.67 | D20: 4.83 | E20: 4.57 | F20: 4.46 | G20: 3.39
B30: 2-hour SLA coverage vs number of new MFCs
B31: New MFCs (p) | C31: Mumbai MMR | D31: Delhi NCR | E31: Bengaluru | F31: Chennai | G31: Kolkata
B32: 0 | C32: 0.7603 | D32: 0.4189 | E32: 0.9327 | F32: 0.8994 | G32: 0.9811
B33: 1 | C33: 0.9258 | D33: 0.7732 | E33: 0.9327 | F33: 0.9294 | G33: 1
B34: 2 | C34: 1 | D34: 0.9585 | E34: 0.9619 | F34: 0.9294 | G34: 1
B35: 3 | C35: 1 | D35: 1 | E35: 0.9886 | F35: 0.9368 | G35: 1
B36: 4 | C36: 1 | D36: 1 | E36: 0.9886 | F36: 0.9842 | G36: 1
B37: 5 | C37: 1 | D37: 1 | E37: 0.9886 | F37: 0.9842 | G37: 1
B47: Five-year NPV vs number of new MFCs (₹)
B48: New MFCs (p) | C48: Mumbai MMR | D48: Delhi NCR | E48: Bengaluru | F48: Chennai | G48: Kolkata
B49: 0 | C49: 0 | D49: 0 | E49: 0 | F49: 0 | G49: 0
B50: 1 | C50: -44249197 | D50: -27129032 | E50: -34995517 | F50: -31325883 | G50: -33202547
B51: 2 | C51: -70147415 | D51: -69457734 | E51: -67674681 | F51: -77813458 | G51: -54028110
B52: 3 | C52: -112557241 | D52: -108271464 | E52: -112153225 | F52: -115688907 | G52: -91505772
B53: 4 | C53: -142593605 | D53: -160116945 | E53: -144604859 | F53: -143673555 | G53: -115100916
B54: 5 | C54: -185219565 | D54: -208405375 | E54: -191840238 | F54: -187667700 | G54: -141584730
B64: All configurations
B65: City | C65: p | D65: Sites | E65: Km/parcel | F65: 2h SLA | G65: MFC parcels/day | H65: Capex ₹ | I65: Opex ₹/yr | J65: Line-haul ₹/yr | K65: Saving Y1 ₹ | L65: NPV ₹ | M65: Break-even parcels/day | N65: Solver
B66: Mumbai MMR | C66: 0 | D66: Current network | E66: 11.89 | F66: 0.7603 | G66: 0 | H66: 0 | I66: 0 | J66: 0 | K66: 0 | L66: 0 | N66: n/a
B67: Mumbai MMR | C67: 1 | D67: Byculla | E67: 8.39 | F67: 0.9258 | G67: 31.3 | H67: 6500000 | I67: 10680000 | J67: 2170332 | K67: 1725400 | L67: -44249197 | M67: 1131 | N67: Optimal
B68: Mumbai MMR | C68: 2 | D68: Thane Majiwada, Byculla | E68: 5.82 | F68: 1 | G68: 81 | H68: 13000000 | I68: 17310000 | J68: 2666674 | K68: 2991399 | L68: -70147415 | M68: 1050 | N68: Optimal
B69: Mumbai MMR | C69: 3 | D69: Kurla, Thane Majiwada, Byculla | E69: 5.27 | F69: 1 | G69: 116.6 | H69: 19500000 | I69: 26100000 | J69: 4214114 | K69: 3263960 | L69: -112557241 | M69: 1458 | N69: Optimal
B70: Mumbai MMR | C70: 4 | D70: Kurla, Thane Majiwada, Airoli, Byculla | E70: 4.77 | F70: 1 | G70: 116.6 | H70: 26000000 | I70: 32190000 | J70: 4993583 | K70: 3510801 | L70: -142593605 | M70: 1684 | N70: Optimal
...

Sheet Facility Economics
B1: Facility Economics
B2: Live five-year NPV of each city's best MFC configuration · edit WACC/growth on 'Master Data & Assumptions' · Python tie-out column
B4: WACC | C4: ='Master Data & Assumptions'!$M$17 | E4: Year t | F4: 1 | G4: 2 | H4: 3 | I4: 4 | J4: 5
B5: Demand growth | C5: ='Master Data & Assumptions'!$M$18
B6: Cash flows and NPV (₹)
B7: City | C7: p | D7: Capex ₹ | E7: Fixed opex ₹/yr | F7: Line-haul ₹/yr | G7: Saving Y1 ₹ | H7: CF Y0 | I7: CF Y1 | J7: CF Y2 | K7: CF Y3 | L7: CF Y4 | M7: CF Y5 | N7: NPV (formula) | O7: NPV (Python) | P7: Tie-out diff | Q7: Break-even x (formula) | R7: Payback
B8: Mumbai MMR | C8: 1 | D8: 6500000 | E8: 10680000 | F8: 2170332 | G8: 1725400 | H8: =-D8 | I8: =$G8*(1+$C$5)^(1-1)-$E8-$F8 | J8: =$G8*(1+$C$5)^(2-1)-$E8-$F8 | K8: =$G8*(1+$C$5)^(3-1)-$E8-$F8 | L8: =$G8*(1+$C$5)^(4-1)-$E8-$F8 | M8: =$G8*(1+$C$5)^(5-1)-$E8-$F8 | N8: =H8+SUMPRODUCT(I8:M8,1/(1+$C$4)^$F$4:$J$4) | O8: -44249197 | P8: =N8-O8 | Q8: =IFERROR((D8+(E8+F8)*SUMPRODUCT(1/(1+$C$4)^$F$4:$J$4))/(G8*SUMPRODUCT((1+$C$5)^($F$4:$J$4-1)/(1+$C$4)^$F$4:$J$4)),"n/a") | R8: =IF(SUM(H8:M8)<0,"> 5 yrs","within 5 yrs")
B9: Delhi NCR | C9: 1 | D9: 6500000 | E9: 7440000 | F9: 2372642 | G9: 2967113 | H9: =-D9 | I9: =$G9*(1+$C$5)^(1-1)-$E9-$F9 | J9: =$G9*(1+$C$5)^(2-1)-$E9-$F9 | K9: =$G9*(1+$C$5)^(3-1)-$E9-$F9 | L9: =$G9*(1+$C$5)^(4-1)-$E9-$F9 | M9: =$G9*(1+$C$5)^(5-1)-$E9-$F9 | N9: =H9+SUMPRODUCT(I9:M9,1/(1+$C$4)^$F$4:$J$4) | O9: -27129032 | P9: =N9-O9 | Q9: =IFERROR((D9+(E9+F9)*SUMPRODUCT(1/(1+$C$4)^$F$4:$J$4))/(G9*SUMPRODUCT((1+$C$5)^($F$4:$J$4-1)/(1+$C$4)^$F$4:$J$4)),"n/a") | R9: =IF(SUM(H9:M9)<0,"> 5 yrs","within 5 yrs")
B10: Bengaluru | C10: 1 | D10: 6500000 | E10: 8022000 | F10: 1184809 | G10: 944465 | H10: =-D10 | I10: =$G10*(1+$C$5)^(1-1)-$E10-$F10 | J10: =$G10*(1+$C$5)^(2-1)-$E10-$F10 | K10: =$G10*(1+$C$5)^(3-1)-$E10-$F10 | L10: =$G10*(1+$C$5)^(4-1)-$E10-$F10 | M10: =$G10*(1+$C$5)^(5-1)-$E10-$F10 | N10: =H10+SUMPRODUCT(I10:M10,1/(1+$C$4)^$F$4:$J$4) | O10: -34995517 | P10: =N10-O10 | Q10: =IFERROR((D10+(E10+F10)*SUMPRODUCT(1/(1+$C$4)^$F$4:$J$4))/(G10*SUMPRODUCT((1+$C$5)^($F$4:$J$4-1)/(1+$C$4)^$F$4:$J$4)),"n/a") | R10: =IF(SUM(H10:M10)<0,"> 5 yrs","within 5 yrs")
B11: Chennai | C11: 1 | D11: 6500000 | E11: 5922000 | F11: 1801647 | G11: 607000 | H11: =-D11 | I11: =$G11*(1+$C$5)^(1-1)-$E11-$F11 | J11: =$G11*(1+$C$5)^(2-1)-$E11-$F11 | K11: =$G11*(1+$C$5)^(3-1)-$E11-$F11 | L11: =$G11*(1+$C$5)^(4-1)-$E11-$F11 | M11: =$G11*(1+$C$5)^(5-1)-$E11-$F11 | N11: =H11+SUMPRODUCT(I11:M11,1/(1+$C$4)^$F$4:$J$4) | O11: -31325883 | P11: =N11-O11 | Q11: =IFERROR((D11+(E11+F11)*SUMPRODUCT(1/(1+$C$4)^$F$4:$J$4))/(G11*SUMPRODUCT((1+$C$5)^($F$4:$J$4-1)/(1+$C$4)^$F$4:$J$4)),"n/a") | R11: =IF(SUM(H11:M11)<0,"> 5 yrs","within 5 yrs")
B12: Kolkata | C12: 1 | D12: 6500000 | E12: 8205000 | F12: 935239 | G12: 1257008 | H12: =-D12 | I12: =$G12*(1+$C$5)^(1-1)-$E12-$F12 | J12: =$G12*(1+$C$5)^(2-1)-$E12-$F12 | K12: =$G12*(1+$C$5)^(3-1)-$E12-$F12 | L12: =$G12*(1+$C$5)^(4-1)-$E12-$F12 | M12: =$G12*(1+$C$5)^(5-1)-$E12-$F12 | N12: =H12+SUMPRODUCT(I12:M12,1/(1+$C$4)^$F$4:$J$4) | O12: -33202547 | P12: =N12-O12 | Q12: =IFERROR((D12+(E12+F12)*SUMPRODUCT(1/(1+$C$4)^$F$4:$J$4))/(G12*SUMPRODUCT((1+$C$5)^($F$4:$J$4-1)/(1+$C$4)^$F$4:$J$4)),"n/a") | R12: =IF(SUM(H12:M12)<0,"> 5 yrs","within 5 yrs")
B13: All cities | D13: =SUM(D8:D12) | E13: =SUM(E8:E12) | F13: =SUM(F8:F12) | G13: =SUM(G8:G12) | H13: =SUM(H8:H12) | I13: =SUM(I8:I12) | J13: =SUM(J8:J12) | K13: =SUM(K8:K12) | ... N13: =SUM(N8:N12)
B35: One-way sensitivity of best-configuration NPV (₹ crore)
B36: Levers: WACC, MFC capex, parcel growth, variable last-mile cost per order-km.
B37: Lever setting | C37: Mumbai MMR | D37: Delhi NCR | E37: Bengaluru | F37: Chennai | G37: Kolkata
B38: capex_pct +0% | C38: -4.4249197 | D38: -2.7129032 | E38: -3.4995517 | F38: -3.1325883 | G38: -3.3202547
B39: capex_pct +20% | C39: -4.5549197 | D39: -2.8429032 | E39: -3.6295517 | F39: -3.2625883 | G39: -3.4502547
B40: capex_pct -20% | C40: -4.2949197 | D40: -2.5829032 | E40: -3.3695517 | F40: -3.0025883 | G40: -3.1902547
B41: growth 18% | C41: -4.4249197 | D41: -2.7129032 | E41: -3.4995517 | F41: -3.1325883 | G41: -3.3202547
B42: growth 28% | C42: -4.2581634 | D42: -2.4261379 | E42: -3.4082711 | F42: -3.073923 | G42: -3.1987676
B43: growth 8% | C43: -4.5650783 | D43: -2.9539292 | E43: -3.5762729 | F43: -3.1818964 | G43: -3.4223646
B44: variable_cost_pct +0% | C44: -4.4249197 | D44: -2.7129032 | E44: -3.4995517 | F44: -3.1325883 | G44: -3.3202547
B45: variable_cost_pct +20% | C45: -4.2534522 | D45: -2.4180363 | E45: -3.4056923 | F45: -3.0722656 | G45: -3.1953353
B46: variable_cost_pct -20% | C46: -4.5963872 | D46: -3.0077701 | E46: -3.5934111 | F46: -3.192911 | G46: -3.4451741
B47: wacc 10% | C47: -4.6143356 | D47: -2.8101094 | E47: -3.64365 | F47: -3.258802 | G47: -3.4541276
B48: wacc 12% | C48: -4.4249197 | D48: -2.7129032 | E48: -3.4995517 | F48: -3.1325883 | G48: -3.3202547
B49: wacc 14% | C49: -4.2498668 | D49: -2.6228093 | E49: -3.3664258 | F49: -3.0160125 | G49: -3.1965285
B51: Tie-out: 'NPV (formula)' is recomputed in Excel from the cash-flow inputs; 'NPV (Python)' is the network_designer output at base assumptions. A non-zero difference appears only when the WACC or growth levers are edited. Break-even = volume multiple at which NPV = 0 with the same sites.

Sheet ML Performance
B1: ML Performance
B2: Time-ordered validation (last 21 days unseen) · models used only where they beat a simple baseline
B4: 0.24303255 | F4: 0.24815725 | J4: 2025-11-09
B5: Travel-time MAE reduction vs planning formula · 10.3 -> 7.8 min | F5: Demand MAE reduction vs seasonal naive · 7.73 -> 5.81 orders/zone-day | J5: Validation window starts
B7: Validation metrics
B8: model | C8: approach | D8: MAE | E8: RMSE | F8: MAPE | G8: n | H8: unit | I8: validation_start
B9: Travel time | C9: Planning formula (baseline) | D9: 10.262 | E9: 16.057 | F9: 16.4 | G9: 12520 | H9: minutes | I9: 2025-11-09
B10: Travel time | C10: Gradient boosting (log ratio) | D10: 7.768 | E10: 12.016 | F10: 12.93 | G10: 12520 | H10: minutes | I10: 2025-11-09
B11: Zone daily demand | C11: Seasonal naive (baseline) | D11: 7.733 | E11: 9.786 | F11: 20.21 | G11: 525 | H11: orders | I11: 2025-11-09
B12: Zone daily demand | C12: Gradient boosting (calendar) | D12: 5.814 | E12: 7.487 | F12: 14.46 | G12: 525 | H12: orders | I12: 2025-11-09
B15: Learned zone travel-time calibration (fed to routing and fleet sizing) | O15: Top travel-time features
B16: Factor > 1 = slower than the network-wide planning formula (congestion, river crossings); < 1 = faster.
B17: City | C17: Zone | D17: Travel-time factor vs plan | O17: feature | P17: importance
B18: Bengaluru | C18: Central Bengaluru | D18: 1.128 | O18: vehicle_type_TWO_WHEELER | P18: 0.26305121
B19: Bengaluru | C19: East Bengaluru | D19: 1.1233 | O19: rain | P19: 0.2020865
B20: Bengaluru | C20: North Bengaluru | D20: 1.1079 | O20: event_traffic | P20: 0.18366725
B21: Bengaluru | C21: South Bengaluru | D21: 1.1128 | O21: city_id_CHE | P21: 0.096326771
B22: Bengaluru | C22: West Bengaluru | D22: 1.1113 | O22: city_id_BLR | P22: 0.080151065
B23: Chennai | C23: Central Chennai | D23: 0.9104 | O23: city_id_KOL | P23: 0.050869713
B24: Chennai | C24: North Chennai | D24: 0.8993 | O24: vehicle_type_VAN_2T | P24: 0.039817344
B25: Chennai | C25: OMR Corridor | D25: 0.8498 | O25: city_id_DEL | P25: 0.028245634
B26: Chennai | C26: South Chennai | D26: 0.8803 | O26: depart_hour | P26: 0.0056371954
B27: Chennai | C27: West Chennai | D27: 0.8776 | O27: haversine_km | P27: 0.0054045844
B28: Delhi NCR | C28: Central Delhi | D28: 0.9564 | O28: dest_zone_OMR Corridor | P28: 0.0045490976
B29: Delhi NCR | C29: Gurugram | D29: 0.9289 | O29: origin_zone_Howrah | P29: 0.0038873083
B30: Delhi NCR | C30: Noida | D30: 0.9097
B31: Delhi NCR | C31: South Delhi | D31: 0.9295
B32: Delhi NCR | C32: West Delhi | D32: 0.9429
B33: Kolkata | C33: Central Kolkata | D33: 1.0766
B34: Kolkata | C34: East Kolkata | D34: 1.039
B35: Kolkata | C35: Howrah | D35: 1.1016
B36: Kolkata | C36: North Kolkata | D36: 1.0519
B37: Kolkata | C37: South Kolkata | D37: 1.058
